```python
try:
    print(a)
except Exception as e:
    print(e.__traceback__.tb_frame.f_globals["__file__"])   # 发生异常所在的文件
    print(e.__traceback__.tb_lineno)                        # 发生异常所在的行数
    print(e)
```

### 2.用traceback模块打印

上述结果看不到具体错误的信息，如行数啥的，不方便调试的时候定位，因此也可以用traceback模块，方便调试

```python
import traceback
try:
    2/0
except Exception as e:
    traceback.print_exc()
    print(traceback.format_exc())
```

结果为：

```python
Traceback (most recent call last):
  File "c:\Users\Administrator\Desktop\test1.py", line 3, in <module>
    2/0
ZeroDivisionError: division by zero
```

ps：上述

还可以用

可以说