Traceback (most recent call last):

File "C:\Program Files\python37\lib\site-packages\django\contrib\sessions\backends\base.py", line 189, in _get_session

return self._session_cache

AttributeError: 'SessionStore' object has no attribute '_session_cache'

During handling of the above exception, another exception occurred:

Traceback (most recent call last):

......

File "C:\Program Files\python37\lib\base64.py", line 87, in b64decode

return binascii.a2b_base64(s)

binascii.Error: Incorrect padding

 

 

**解决方案：将数据库中django_session表数据清空**

 

事情经过：

 

根本原因：

[](https://stackoverflow.com/questions/ask)

```python
    Unhandled exception in thread started by <function wrapper at 0x0000000003FFD278
    >
    Traceback (most recent call last):
...
      File "C:\Python27\Lib\site-packages\rest_framework\generics.py", line 8, in <m
    odule>
        from rest_framework import views, mixins
      File "C:\Python27\Lib\site-packages\rest_framework\views.py", line 14, in <mod
    ule>
        from rest_framework.response import Response
      File "C:\Python27\Lib\site-packages\rest_framework\response.py", line 8, in <m
    odule>
        from django.core.handlers.wsgi import STATUS_CODE_TEXT
    ImportError: cannot import name STATUS_CODE_TEXT
```

如果Django版本为2.0.9

解决方案： 升级 djangorestframework==3.10.0

```
pip3 install  djangorestframework==3.10.0
```

# 报错:cannot import name ‘six‘ from ‘django.utils‘

解决方案：如果Django版本为2.0.9，安装django-util-six==2.0

```
pip3 install django-util-six
```